Workbook

Sheet KET
A1: NO | B1: NAMA TOKO | C1: GRSM | D1: AREA | E1: NAMA TL | F1: CHANNEL GROUP | I1: PRODUCT | J1: VARIANT
A2: 1 | B2: MG CIANJUR | C2: GRSM 3A | D2: CIANJUR | E2: FAHMI LUKMANUL HAKIM | F2: GMM | I2: WOW | J2: CARBONARA
A3: =A2+1 -> 2 | B3: MULTI GROSIR STASIUN | C3: GRSM 3A | D3: SUKABUMI | E3: FAHMI LUKMANUL HAKIM | F3: GMM | I3: WOW | J3: BOLOGNESE
A4: =A3+1 -> 3 | B4: M ZAMZAM TK (M2) | C4: GRSM 4 | D4: TASIK | E4: FAHMI LUKMANUL HAKIM | F4: GMM
A5: =A4+1 -> 4 | B5: SAMUDRA BANJAR | C5: GRSM 4 | D5: BANJAR | E5: FAHMI LUKMANUL HAKIM | F5: GMM | I5: WOW | J5: AGLIO OLIO
A6: =A5+1 -> 5 | B6: MITRA INDAH | C6: GRSM 4 | D6: KUNINGAN | E6: FAHMI LUKMANUL HAKIM | F6: GMM | I6: WOW | J6: GORENG
A7: =A6+1 -> 6 | B7: FAJAR JALAKSANA | C7: GRSM 4 | D7: KUNINGAN | E7: FAHMI LUKMANUL HAKIM | F7: GMM
A8: =A7+1 -> 7 | B8: PRATAMA PUTRA BANYURESMI | C8: GRSM 4 | D8: GARUT | E8: FAHMI LUKMANUL HAKIM | F8: GMM
A9: =A8+1 -> 8 | B9: PRATAMA PUTRA CIHUNI | C9: GRSM 4 | D9: GARUT | E9: FAHMI LUKMANUL HAKIM | F9: GMM
A10: =A9+1 -> 9 | B10: ASIA GARUT | C10: GRSM 4 | D10: GARUT | E10: FAHMI LUKMANUL HAKIM | F10: GMM
A11: =A10+1 -> 10 | B11: KAIRO | C11: GRSM 4 | D11: TASIK | E11: FAHMI LUKMANUL HAKIM | F11: GMM
A12: =A11+1 -> 11 | B12: KAIRO MAJALAYA | C12: GRSM 4 | D12: MAJALAYA | E12: FAHMI LUKMANUL HAKIM | F12: GMM
A13: =A12+1 -> 12 | B13: GRIYA SUMEDANG | C13: GRSM 4 | D13: BANDUNG | E13: FAHMI LUKMANUL HAKIM | F13: NKA
A14: =A13+1 -> 13 | B14: ASIA PLAZA TASIK | C14: GRSM 4 | D14: TASIKMALAYA | E14: FAHMI LUKMANUL HAKIM | F14: GMM
A15: =A14+1 -> 14 | B15: SAHABAT | C15: GRSM 4 | D15: KUNINGAN | E15: FAHMI LUKMANUL HAKIM | F15: GMM
A16: =A15+1 -> 15 | B16: TOKMA CADIKA SM. | C16: GRSM 4 | D16: SUBANG | E16: FAHMI LUKMANUL HAKIM | F16: GMM
A17: =A16+1 -> 16 | B17: YOGYA HZ* | C17: GRSM 4 | D17: TASIKMALAYA | E17: FAHMI LUKMANUL HAKIM | F17: GMM
A18: =A17+1 -> 17 | B18: YOGYA BANJAR * | C18: GRSM 4 | D18: BANJAR | E18: FAHMI LUKMANUL HAKIM | F18: GMM
... A43: =A42+1 -> 42 | B43: CHANDRA TANJUNG KARANG | C43: GRSM 2 | D43: LAMPUNG | E43: AFNITA SARI | F43: MT
A44: =A43+1 -> 43 | B44: #.PINUS MM BANJARBARU | C44: GRSM 7 | D44: BANJARMASIN | E44: INDRI | F44: GMM | I44: WOW
A45: =A44+1 -> 44 | B45: ADIJAYA TELUK | C45: GRSM 5 | D45: TEGAL | E45: SUPRIYATI | F45: GMM | I45: WOW
A46: =A45+1 -> 45 | B46: ASIA TOSERBA CIHIDENG | C46: GRSM 4 | D46: TASIKMALAYA | E46: FAHMI LUKMANUL HAKIM | F46: NKA | I46: WOW
A47: =A46+1 -> 46 | B47: BASA BANJARAN | C47: GRSM 5 | D47: TEGAL | E47: SUPRIYATI | F47: GMM | I47: WOW
A48: =A47+1 -> 47 | B48: BRAVO SUPERMARKET TULUNGAGUNG | C48: GRSM 6 | D48: TULUNGAGUNG | E48: MARTIKA MINTOROWATI | F48: GMM | I48: WOW
A49: =A48+1 -> 48 | B49: BRAVO SWALAYAN JATENG | C49: GRSM 5 | D49: BLORA | E49: SUPRIYATI | F49: GMM | I49: WOW
A50: =A49+1 -> 49 | B50: EKA SURYA PLAZA | C50: GRSM 5 | D50: PURBALINGGA | E50: SUPRIYATI | F50: GMM | I50: WOW
A51: =A50+1 -> 50 | B51: GUNASALMA 1 KAWALI | C51: GRSM 4 | D51: CIAMIS | E51: FAHMI LUKMANUL HAKIM | F51: GMM | I51: WOW
A52: =A51+1 -> 51 | B52: GUNASALMA 3 | C52: GRSM 4 | D52: TASIKMALAYA | E52: FAHMI LUKMANUL HAKIM | F52: GMM | I52: WOW
A53: =A52+1 -> 52 | B53: ISTANA TOSERBA | C53: GRSM 6 | D53: TULUNGAGUNG | E53: MARTIKA MINTOROWATI | F53: GMM | I53: WOW
A54: =A53+1 -> 53 | B54: LANGGAN MAJALAYA | C54: GRSM 4 | D54: MAJALAYA | E54: FAHMI LUKMANUL HAKIM | F54: GMM | I54: WOW
A55: =A54+1 -> 54 | B55: LUWES PURWODADI | C55: GRSM 5 | D55: REMBANG | E55: SUPRIYATI | F55: MT | I55: WOW
... A66: =A65+1 -> 65 | B66: YOVA GUNUNG MALANG | C66: GRSM 7 | D66: BALIKPAPAN | E66: INDRI | F66: GMM | I66: WOW
A67: 67 | B67: TRIO JAYA WONOSOBO | C67: GRSM 5 | D67: WONOSOBO | E67: SUPRIYATI | F67: GMM

Sheet Kode Outlet dan Target Toko
A1: GRSM | B1: RSM | C1: Kode Subdist | D1: Kode Outlet | E1: Nama Toko | F1: Target Sell Out SPG/day (value)
A2: GRSM 3A | B2: CIANJUR | C2: 211019 | D2: 1556924 | E2: MG CIANJUR | F2: 2000000
A3: GRSM 3A | B3: SUKABUMI | C3: 103272 | D3: 1178 | E3: MULTI GROSIR STASIUN | F3: 2000000
A4: GRSM 4 | B4: TASIK | C4: 103259 | D4: 9013525 | E4: M ZAMZAM TK (M2) | F4: 2000000
A5: GRSM 4 | B5: BANJAR | C5: 103258 | D5: 9210369 | E5: SAMUDRA BANJAR | F5: 2000000
A6: GRSM 4 | B6: KUNINGAN | C6: 103277 | D6: 6300538 | E6: MITRA INDAH | F6: 2000000
A7: GRSM 4 | B7: KUNINGAN | C7: 103277 | D7: 6301424 | E7: FAJAR JALAKSANA | F7: 2000000
A8: GRSM 4 | B8: TASIK | C8: 103259 | D8: 9029389 | E8: KAIRO | F8: 2000000
A9: GRSM 4 | B9: BANDUNG | C9: 490034 | D9: 209554 | E9: GRIYA SUMEDANG | F9: 2000000
A10: GRSM 4 | B10: MAJALAYA | C10: 103259 | D10: 9029389 | E10: KAIRO MAJALAYA | F10: 2000000
A11: GRSM 4 | B11: GARUT | C11: 189901 | D11: 1602016 | E11: ASIA GARUT | F11: 2000000
A12: GRSM 4 | B12: GARUT | C12: 103257 | D12: 9162509 | E12: PRATAMA PUTRA BANYURESMI | F12: 2000000
A13: GRSM 4 | B13: GARUT | C13: 103257 | D13: 9162509 | E13: PRATAMA PUTRA CIHUNI | F13: 2000000
... A74: GRSM 5 | B74: WONOSOBO | C74: 0 | D74: 0 | E74: TRIO JAYA WONOSOBO | F74: 2000000

Sheet Sheet1
A1: WEEK | B1: 28
A2: NAMA TL | B2: FAHMI LUKMANUL HAKIM
A4: Sum of TOTAL SELLING (RP) | B4: Column Labels
A5: Row Labels | B5: 46213 | C5: 46214 | D5: 46215 | E5: Grand Total
A6: ASIA GARUT | B6: 3168800 | C6: 2856000 | D6: 3400000 | E6: 9424800
A7: BUNGA | B7: 1584400 | C7: 1428000 | D7: 1700000 | E7: 4712400
A8: MAULIDA FHATIRRAHMAN | B8: 1584400 | C8: 1428000 | D8: 1700000 | E8: 4712400
A9: ASIA PLAZA TASIK | B9: 2332750 | C9: 2266100 | D9: 2756300 | E9: 7355150
A10: NURLAELA SITI SALEHA | B10: 1148100 | C10: 1150250 | D10: 1399650 | E10: 3698000
A11: RISKA APRILIANI | B11: 1184650 | C11: 1115850 | D11: 1356650 | E11: 3657150
A12: GRIYA SUMEDANG | B12: 1591650 | C12: 2023950 | D12: 1932250 | E12: 5547850
A13: LIA NUR FITRIANI | B13: 795825 | C13: 1011975 | D13: 966125 | E13: 2773925
A14: YULIAWATI | B14: 795825 | C14: 1011975 | D14: 966125 | E14: 2773925
A15: KAIRO MAJALAYA | B15: 2337000 | C15: 2313000 | D15: 2541000 | E15: 7191000
A16: MEISYA AYU ANDREANI | B16: 1209000 | C16: 1131000 | D16: 1251000 | E16: 3591000
A17: SINTA NURLAELA | B17: 1128000 | C17: 1182000 | D17: 1290000 | E17: 3600000
... A30: YOGYA HZ* | B30: 1650000 | C30: 2211000 | D30: 1320000 | E30: 5181000
A31: MIRA SARASWATI | B31: 825000 | C31: 1089000 | E31: 1914000
A32: NITA ARDIANTI | B32: 825000 | C32: 1122000 | D32: 660000 | E32: 2607000
A33: YUNI | D33: 660000 | E33: 660000
A34: Grand Total | B34: 16867800 | C34: 18720750 | D34: 19425750 | E34: 55014300

Sheet Sheet2
A1: WEEK | B1: 34
A2: NAMA TL | B2: (All)
A4: Sum of TOTAL SELLING (RP) | C4: TANGGAL
A5: NAMA TOKO | B5: NAMA SPG | C5: 46257 | D5: 46255 | E5: 46256 | F5: 46252 | G5: Grand Total
A6: PRATAMA PUTRA CIHUNI | B6: NENG NURJANAH | C6: 533200 | D6: 604560 | E6: 616900 | G6: 1754660
B7: ELSA TIAS NURPADILAH | C7: 527000 | D7: 589056 | E7: 604500 | G7: 1720556
A8: MG CIANJUR | B8: LIANI ISMIATI | D8: 800926 | E8: 980880 | F8: 2459726 | G8: 4241532
B9: ALDA AGUSTINA | D9: 800926 | E9: 980880 | F9: 2459726 | G9: 4241532
A10: LANGGAN MAJALAYA | B10: MEISYA AYU ANDREANI | C10: 666000 | D10: 594000 | E10: 642000 | G10: 1902000
B11: SINTA NURLAELA | C11: 678000 | D11: 564000 | E11: 621000 | G11: 1863000
A12: ASIA TOSERBA CIHIDENG | B12: NURLAELA SITI SALEHA | C12: 741750 | D12: 741750 | E12: 806250 | G12: 2289750
B13: RISKA APRILIANI | C13: 765400 | D13: 703050 | E13: 761100 | G13: 2229550
A14: MITRA BUANA PASAR WETAN | B14: MEGA FITRIA | C14: 255156 | D14: 211314 | E14: 59010 | G14: 525480
B15: DITA NINDIA | C15: 220362 | D15: 58908 | E15: 70812 | G15: 350082
A16: YOGYA GRAND SUBANG | B16: TITIN NURJANAH | C16: 1326375 | D16: 962850 | E16: 802375 | G16: 3091600
B17: TUTI NURHASANAH | C17: 1326375 | D17: 962850 | E17: 802375 | G17: 3091600
A18: GUNASALMA 3 | B18: YUNIATI | C18: 450000 | D18: 412000 | E18: 426000 | G18: 1288000
B19: SHOFA DWINA | C19: 450000 | D19: 412000 | E19: 426000 | G19: 1288000
A20: GUNASALMA 1 KAWALI | B20: GITA DEWI MEIYANI | C20: 372000 | D20: 294000 | E20: 692000 | G20: 1358000
B21: HANA | C21: 372000 | D21: 294000 | E21: 692000 | G21: 1358000
A22: BASA BANJARAN | B22: FHARADILLA APRIZIAH WARDANI | D22: 1182000 | E22: 1356000 | G22: 2538000
B23: SELLY SRI WULANDARI | C23: 1422000 | D23: 1182000 | E23: 1356000 | G23: 3960000
B24: SUGIARTI | C24: 1422000 | G24: 1422000
A25: TRIO PLAZA | B25: SRI PUJIYATI | C25: 834030 | D25: 831870 | E25: 839970 | G25: 2505870
B26: FENNI ROSANTI | C26: 834030 | D26: 831870 | E26: 839970 | G26: 2505870
A27: MUTIARA CAHAYA MEJASEM | B27: AINUN NAJIKHA | C27: 1351480 | D27: 1151150 | E27: 1312610 | G27: 3815240
B28: SHEILLA NAVISYA | C28: 1351480 | D28: 1151150 | E28: 1312610 | G28: 3815240
A29: #.PINUS MM BANJARBARU | B29: SALSHABILLA PUTERI HARIANTO | C29: 582400 | D29: 608000 | E29: 588800 | G29: 1779200
B30: ISNAWATI | C30: 582400 | D30: 608000 | E30: 588800 | G30: 1779200
B31: INDRIANING PUJI ASTUTI | C31: 582400 | D31: 608000 | E31: 588800 | G31: 1779200
A32: PLANET SWALAYAN.MM | B32: GADIS | C32: 863928 | D32: 422477 | E32: 633616 | G32: 1920021
B33: SUCITRAMADHANI MUKTHI | C33: 863928 | D33: 422477 | E33: 633616 | G33: 1920021
A34: TOP SWALAYAN | B34: JENNITA PUSPITA SARI | C34: 817150 | D34: 1300950 | E34: 840750 | G34: 2958850
B35: AYU FITRI WULANDARI | C35: 817150 | D35: 1300950 | E35: 840750 | G35: 2958850
A36: BRAVO SUPERMARKET TULUNGAGUNG | B36: RATNA DYAH OKTAVIANA | C36: 1519050 | D36: 1541850 | E36: 1410750 | G36: 4471650
B37: SUSMIATI | C37: 1519050 | D37: 1541850 | E37: 1410750 | G37: 4471650
A38: PRIMA SWALAYAN | B38: ELY NURAINI | C38: 870000 | D38: 756000 | E38: 858000 | G38: 2484000
B39: SITI KUSNUL | C39: 870000 | D39: 756000 | E39: 858000 | G39: 2484000
A40: CV TOP | B40: IKA PUSPITA YULIANI | C40: 501700 | D40: 442500 | E40: 484300 | G40: 1428500
B41: SUSI SUSANTI | C41: 501700 | D41: 442500 | E41: 484300 | G41: 1428500
...

Sheet DAILY REPORT
A1: DAILY REPORT GMM WOW SPAGHETTI JSM
A2: *Pengisian dengan huruf CAPITAL | F2: : Jangan copas/edit ke tanda berwarna ini!
A5: ISI MANUAL | B5: RUMUS | C5: isi manual dengan format "18/05/26" | D5: RUMUS | E5: RUMUS | F5: RUMUS | G5: RUMUS | H5: RUMUS | I5: Pilihan | J5: ISI MANUAL | K5: Pilihan | L5: ISI MANUAL | M5: ISI MANUAL | N5: RUMUS | O5: ISI MANUAL
A6: WEEK | B6: BULAN | C6: TANGGAL | D6: GRSM | E6: NAMA TL | F6: CHANNEL GROUP | G6: Kode Subdist | H6: Kode Outlet | I6: NAMA TOKO | J6: NAMA SPG | K6: VARIANT | L6: HARGA JUAL (PCS) | M6: QTY SELLING (PCS) | N6: TOTAL SELLING (RP) | O6: SAMPLING YANG KELUAR (CUP)
A7: 22 | B7: =IF(C7="","",UPPER(TEXT(C7, "MMM"))) -> MAY | C7: 46171 | D7: {=IFERROR(INDEX('Kode Outlet dan Target Toko'!$A:$A,MATCH($I7,'Kode Outlet dan Target Toko'!$E:$E,0)),"")} -> GRSM 4 | E7: =IFERROR(VLOOKUP(I7,KET!$B:$F,4,0),"") -> FAHMI LUKMANUL HAKIM | F7: =IFERROR(VLOOKUP(I7,KET!$B:$F,5,0),"") -> GMM | G7: =IFERROR(INDEX('Kode Outlet dan Target Toko'!$C:$C,MATCH($I7,'Kode Outlet dan Target Toko'!$E:$E,0)),0) -> 103259 | H7: =IFERROR(INDEX('Kode Outlet dan Target Toko'!$D:$D,MATCH($I7,'Kode Outlet dan Target Toko'!$E:$E,0)),0) -> 9029389 | I7: KAIRO | J7: GINA FITRIANTI NUGRAHA | K7: CARBONARA | L7: 2000 | M7: 63 | N7: =IFERROR(M7*L7,"") -> 126000
A8: 22 | B8: =IF(C8="","",UPPER(TEXT(C8, "MMM"))) -> MAY | C8: 46171 | D8: {=IFERROR(INDEX('Kode Outlet dan Target Toko'!$A:$A,MATCH($I8,'Kode Outlet dan Target Toko'!$E:$E,0)),"")} -> GRSM 4 | E8: =IFERROR(VLOOKUP(I8,KET!$B:$F,4,0),"") -> FAHMI LUKMANUL HAKIM | F8: =IFERROR(VLOOKUP(I8,KET!$B:$F,5,0),"") -> GMM | G8: =IFERROR(INDEX('Kode Outlet dan Target Toko'!$C:$C,MATCH($I8,'Kode Outlet dan Target Toko'!$E:$E,0)),0) -> 103259 | H8: =IFERROR(INDEX('Kode Outlet dan Target Toko'!$D:$D,MATCH($I8,'Kode Outlet dan Target Toko'!$E:$E,0)),0) -> 9029389 | I8: KAIRO | J8: GINA FITRIANTI NUGRAHA | K8: AGLIO OLIO | L8: 2000 | M8: 27 | N8: =IFERROR(M8*L8,"") -> 54000
A9: 22 | B9: =IF(C9="","",UPPER(TEXT(C9, "MMM"))) -> MAY | C9: 46171 | D9: {=IFERROR(INDEX('Kode Outlet dan Target Toko'!$A:$A,MATCH($I9,'Kode Outlet dan Target Toko'!$E:$E,0)),"")} -> GRSM 4 | E9: =IFERROR(VLOOKUP(I9,KET!$B:$F,4,0),"") -> FAHMI LUKMANUL HAKIM | F9: =IFERROR(VLOOKUP(I9,KET!$B:$F,5,0),"") -> GMM | G9: =IFERROR(INDEX('Kode Outlet dan Target Toko'!$C:$C,MATCH($I9,'Kode Outlet dan Target Toko'!$E:$E,0)),0) -> 103259 | H9: =IFERROR(INDEX('Kode Outlet dan Target Toko'!$D:$D,MATCH($I9,'Kode Outlet dan Target Toko'!$E:$E,0)),0) -> 9029389 | I9: KAIRO | J9: GINA FITRIANTI NUGRAHA | K9: GORENG | L9: 2000 | M9: 189 | N9: =IFERROR(M9*L9,"") -> 378000
A10: 22 | B10: =IF(C10="","",UPPER(TEXT(C10, "MMM"))) -> MAY | C10: 46171 | D10: {=IFERROR(INDEX('Kode Outlet dan Target Toko'!$A:$A,MATCH($I10,'Kode Outlet dan Target Toko'!$E:$E,0)),"")} -> GRSM 4 | E10: =IFERROR(VLOOKUP(I10,KET!$B:$F,4,0),"") -> FAHMI LUKMANUL HAKIM | F10: =IFERROR(VLOOKUP(I10,KET!$B:$F,5,0),"") -> GMM | G10: =IFERROR(INDEX('Kode Outlet dan Target Toko'!$C:$C,MATCH($I10,'Kode Outlet dan Target Toko'!$E:$E,0)),0) -> 103259 | H10: =IFERROR(INDEX('Kode Outlet dan Target Toko'!$D:$D,MATCH($I10,'Kode Outlet dan Target Toko'!$E:$E,0)),0) -> 9029389 | I10: KAIRO | J10: MEGA FITRIA | K10: BOLOGNESE | L10: 2000 | M10: 51 | N10: =IFERROR(M10*L10,"") -> 102000 | O10: 120
A11: 22 | B11: =IF(C11="","",UPPER(TEXT(C11, "MMM"))) -> MAY | C11: 46171 | D11: {=IFERROR(INDEX('Kode Outlet dan Target Toko'!$A:$A,MATCH($I11,'Kode Outlet dan Target Toko'!$E:$E,0)),"")} -> GRSM 4 | E11: =IFERROR(VLOOKUP(I11,KET!$B:$F,4,0),"") -> FAHMI LUKMANUL HAKIM | F11: =IFERROR(VLOOKUP(I11,KET!$B:$F,5,0),"") -> GMM | G11: =IFERROR(INDEX('Kode Outlet dan Target Toko'!$C:$C,MATCH($I11,'Kode Outlet dan Target Toko'!$E:$E,0)),0) -> 103259 | H11: =IFERROR(INDEX('Kode Outlet dan Target Toko'!$D:$D,MATCH($I11,'Kode Outlet dan Target Toko'!$E:$E,0)),0) -> 9029389 | I11: KAIRO | J11: MEGA FITRIA | K11: CARBONARA | L11: 2000 | M11: 54 | N11: =IFERROR(M11*L11,"") -> 108000
A12: 22 | B12: =IF(C12="","",UPPER(TEXT(C12, "MMM"))) -> MAY | C12: 46171 | D12: {=IFERROR(INDEX('Kode Outlet dan Target Toko'!$A:$A,MATCH($I12,'Kode Outlet dan Target Toko'!$E:$E,0)),"")} -> GRSM 4 | E12: =IFERROR(VLOOKUP(I12,KET!$B:$F,4,0),"") -> FAHMI LUKMANUL HAKIM | F12: =IFERROR(VLOOKUP(I12,KET!$B:$F,5,0),"") -> GMM | G12: =IFERROR(INDEX('Kode Outlet dan Target Toko'!$C:$C,MATCH($I12,'Kode Outlet dan Target Toko'!$E:$E,0)),0) -> 103259 | H12: =IFERROR(INDEX('Kode Outlet dan Target Toko'!$D:$D,MATCH($I12,'Kode Outlet dan Target Toko'!$E:$E,0)),0) -> 9029389 | I12: KAIRO | J12: MEGA FITRIA | K12: AGLIO OLIO | L12: 2000 | M12: 39 | N12: =IFERROR(M12*L12,"") -> 78000
A13: 22 | B13: =IF(C13="","",UPPER(TEXT(C13, "MMM"))) -> MAY | C13: 46171 | D13: {=IFERROR(INDEX('Kode Outlet dan Target Toko'!$A:$A,MATCH($I13,'Kode Outlet dan Target Toko'!$E:$E,0)),"")} -> GRSM 4 | E13: =IFERROR(VLOOKUP(I13,KET!$B:$F,4,0),"") -> FAHMI LUKMANUL HAKIM | F13: =IFERROR(VLOOKUP(I13,KET!$B:$F,5,0),"") -> GMM | G13: =IFERROR(INDEX('Kode Outlet dan Target Toko'!$C:$C,MATCH($I13,'Kode Outlet dan Target Toko'!$E:$E,0)),0) -> 103259 | H13: =IFERROR(INDEX('Kode Outlet dan Target Toko'!$D:$D,MATCH($I13,'Kode Outlet dan Target Toko'!$E:$E,0)),0) -> 9029389 | I13: KAIRO | J13: MEGA FITRIA | K13: GORENG | L13: 2000 | M13: 129 | N13: =IFERROR(M13*L13,"") -> 258000
A14: 22 | B14: =IF(C14="","",UPPER(TEXT(C14, "MMM"))) -> MAY | C14: 46171 | D14: {=IFERROR(INDEX('Kode Outlet dan Target Toko'!$A:$A,MATCH($I14,'Kode Outlet dan Target Toko'!$E:$E,0)),"")} -> GRSM 4 | E14: =IFERROR(VLOOKUP(I14,KET!$B:$F,4,0),"") -> FAHMI LUKMANUL HAKIM | F14: =IFERROR(VLOOKUP(I14,KET!$B:$F,5,0),"") -> GMM | G14: =IFERROR(INDEX('Kode Outlet dan Target Toko'!$C:$C,MATCH($I14,'Kode Outlet dan Target Toko'!$E:$E,0)),0) -> 103259 | H14: =IFERROR(INDEX('Kode Outlet dan Target Toko'!$D:$D,MATCH($I14,'Kode Outlet dan Target Toko'!$E:$E,0)),0) -> 9029389 | I14: KAIRO | J14: GINA FITRIANTI NUGRAHA | K14: BOLOGNESE | L14: 2000 | M14: 75 | N14: =IFERROR(M14*L14,"") -> 150000 | O14: 120
A15: 22 | B15: =IF(C15="","",UPPER(TEXT(C15, "MMM"))) -> MAY | C15: 46172 | D15: {=IFERROR(INDEX('Kode Outlet dan Target Toko'!$A:$A,MATCH($I15,'Kode Outlet dan Target Toko'!$E:$E,0)),"")} -> GRSM 4 | E15: =IFERROR(VLOOKUP(I15,KET!$B:$F,4,0),"") -> FAHMI LUKMANUL HAKIM | F15: =IFERROR(VLOOKUP(I15,KET!$B:$F,5,0),"") -> GMM | G15: =IFERROR(INDEX('Kode Outlet dan Target Toko'!$C:$C,MATCH($I15,'Kode Outlet dan Target Toko'!$E:$E,0)),0) -> 103259 | H15: =IFERROR(INDEX('Kode Outlet dan Target Toko'!$D:$D,MATCH($I15,'Kode Outlet dan Target Toko'!$E:$E,0)),0) -> 9029389 | I15: KAIRO | J15: GINA FITRIANTI NUGRAHA | K15: CARBONARA | L15: 2000 | M15: 84 | N15: =IFERROR(M15*L15,"") -> 168000
A16: 22 | B16: =IF(C16="","",UPPER(TEXT(C16, "MMM"))) -> MAY | C16: 46172 | D16: {=IFERROR(INDEX('Kode Outlet dan Target Toko'!$A:$A,MATCH($I16,'Kode Outlet dan Target Toko'!$E:$E,0)),"")} -> GRSM 4 | E16: =IFERROR(VLOOKUP(I16,KET!$B:$F,4,0),"") -> FAHMI LUKMANUL HAKIM | F16: =IFERROR(VLOOKUP(I16,KET!$B:$F,5,0),"") -> GMM | G16: =IFERROR(INDEX('Kode Outlet dan Target Toko'!$C:$C,MATCH($I16,'Kode Outlet dan Target Toko'!$E:$E,0)),0) -> 103259 | H16: =IFERROR(INDEX('Kode Outlet dan Target Toko'!$D:$D,MATCH($I16,'Kode Outlet dan Target Toko'!$E:$E,0)),0) -> 9029389 | I16: KAIRO | J16: GINA FITRIANTI NUGRAHA | K16: AGLIO OLIO | L16: 2000 | M16: 54 | N16: =IFERROR(M16*L16,"") -> 108000
A17: 22 | B17: =IF(C17="","",UPPER(TEXT(C17, "MMM"))) -> MAY | C17: 46172 | D17: {=IFERROR(INDEX('Kode Outlet dan Target Toko'!$A:$A,MATCH($I17,'Kode Outlet dan Target Toko'!$E:$E,0)),"")} -> GRSM 4 | E17: =IFERROR(VLOOKUP(I17,KET!$B:$F,4,0),"") -> FAHMI LUKMANUL HAKIM | F17: =IFERROR(VLOOKUP(I17,KET!$B:$F,5,0),"") -> GMM | G17: =IFERROR(INDEX('Kode Outlet dan Target Toko'!$C:$C,MATCH($I17,'Kode Outlet dan Target Toko'!$E:$E,0)),0) -> 103259 | H17: =IFERROR(INDEX('Kode Outlet dan Target Toko'!$D:$D,MATCH($I17,'Kode Outlet dan Target Toko'!$E:$E,0)),0) -> 9029389 | I17: KAIRO | J17: GINA FITRIANTI NUGRAHA | K17: GORENG | L17: 2000 | M17: 90 | N17: =IFERROR(M17*L17,"") -> 180000
A18: 22 | B18: =IF(C18="","",UPPER(TEXT(C18, "MMM"))) -> MAY | C18: 46172 | D18: {=IFERROR(INDEX('Kode Outlet dan Target Toko'!$A:$A,MATCH($I18,'Kode Outlet dan Target Toko'!$E:$E,0)),"")} -> GRSM 4 | E18: =IFERROR(VLOOKUP(I18,KET!$B:$F,4,0),"") -> FAHMI LUKMANUL HAKIM | F18: =IFERROR(VLOOKUP(I18,KET!$B:$F,5,0),"") -> GMM | G18: =IFERROR(INDEX('Kode Outlet dan Target Toko'!$C:$C,MATCH($I18,'Kode Outlet dan Target Toko'!$E:$E,0)),0) -> 103259 | H18: =IFERROR(INDEX('Kode Outlet dan Target Toko'!$D:$D,MATCH($I18,'Kode Outlet dan Target Toko'!$E:$E,0)),0) -> 9029389 | I18: KAIRO | J18: MEGA FITRIA | K18: BOLOGNESE | L18: 2000 | M18: 81 | N18: =IFERROR(M18*L18,"") -> 162000 | O18: 160
A19: 22 | B19: =IF(C19="","",UPPER(TEXT(C19, "MMM"))) -> MAY | C19: 46172 | D19: {=IFERROR(INDEX('Kode Outlet dan Target Toko'!$A:$A,MATCH($I19,'Kode Outlet dan Target Toko'!$E:$E,0)),"")} -> GRSM 4 | E19: =IFERROR(VLOOKUP(I19,KET!$B:$F,4,0),"") -> FAHMI LUKMANUL HAKIM | F19: =IFERROR(VLOOKUP(I19,KET!$B:$F,5,0),"") -> GMM | G19: =IFERROR(INDEX('Kode Outlet dan Target Toko'!$C:$C,MATCH($I19,'Kode Outlet dan Target Toko'!$E:$E,0)),0) -> 103259 | H19: =IFERROR(INDEX('Kode Outlet dan Target Toko'!$D:$D,MATCH($I19,'Kode Outlet dan Target Toko'!$E:$E,0)),0) -> 9029389 | I19: KAIRO | J19: MEGA FITRIA | K19: CARBONARA | L19: 2000 | M19: 69 | N19: =IFERROR(M19*L19,"") -> 138000
A20: 22 | B20: =IF(C20="","",UPPER(TEXT(C20, "MMM"))) -> MAY | C20: 46172 | D20: {=IFERROR(INDEX('Kode Outlet dan Target Toko'!$A:$A,MATCH($I20,'Kode Outlet dan Target Toko'!$E:$E,0)),"")} -> GRSM 4 | E20: =IFERROR(VLOOKUP(I20,KET!$B:$F,4,0),"") -> FAHMI LUKMANUL HAKIM | F20: =IFERROR(VLOOKUP(I20,KET!$B:$F,5,0),"") -> GMM | G20: =IFERROR(INDEX('Kode Outlet dan Target Toko'!$C:$C,MATCH($I20,'Kode Outlet dan Target Toko'!$E:$E,0)),0) -> 103259 | H20: =IFERROR(INDEX('Kode Outlet dan Target Toko'!$D:$D,MATCH($I20,'Kode Outlet dan Target Toko'!$E:$E,0)),0) -> 9029389 | I20: KAIRO | J20: MEGA FITRIA | K20: AGLIO OLIO | L20: 2000 | M20: 57 | N20: =IFERROR(M20*L20,"") -> 114000
A21: 22 | B21: =IF(C21="","",UPPER(TEXT(C21, "MMM"))) -> MAY | C21: 46172 | D21: {=IFERROR(INDEX('Kode Outlet dan Target Toko'!$A:$A,MATCH($I21,'Kode Outlet dan Target Toko'!$E:$E,0)),"")} -> GRSM 4 | E21: =IFERROR(VLOOKUP(I21,KET!$B:$F,4,0),"") -> FAHMI LUKMANUL HAKIM | F21: =IFERROR(VLOOKUP(I21,KET!$B:$F,5,0),"") -> GMM | G21: =IFERROR(INDEX('Kode Outlet dan Target Toko'!$C:$C,MATCH($I21,'Kode Outlet dan Target Toko'!$E:$E,0)),0) -> 103259 | H21: =IFERROR(INDEX('Kode Outlet dan Target Toko'!$D:$D,MATCH($I21,'Kode Outlet dan Target Toko'!$E:$E,0)),0) -> 9029389 | I21: KAIRO | J21: MEGA FITRIA | K21: GORENG | L21: 2000 | M21: 72 | N21: =IFERROR(M21*L21,"") -> 144000
A22: 22 | B22: =IF(C22="","",UPPER(TEXT(C22, "MMM"))) -> MAY | C22: 46172 | D22: {=IFERROR(INDEX('Kode Outlet dan Target Toko'!$A:$A,MATCH($I22,'Kode Outlet dan Target Toko'!$E:$E,0)),"")} -> GRSM 4 | E22: =IFERROR(VLOOKUP(I22,KET!$B:$F,4,0),"") -> FAHMI LUKMANUL HAKIM | F22: =IFERROR(VLOOKUP(I22,KET!$B:$F,5,0),"") -> GMM | G22: =IFERROR(INDEX('Kode Outlet dan Target Toko'!$C:$C,MATCH($I22,'Kode Outlet dan Target Toko'!$E:$E,0)),0) -> 103259 | H22: =IFERROR(INDEX('Kode Outlet dan Target Toko'!$D:$D,MATCH($I22,'Kode Outlet dan Target Toko'!$E:$E,0)),0) -> 9029389 | I22: KAIRO | J22: MEGA FITRIA | K22: BOLOGNESE | L22: 2000 | M22: 72 | N22: =IFERROR(M22*L22,"") -> 144000 | O22: 160
A23: 22 | B23: =IF(C23="","",UPPER(TEXT(C23, "MMM"))) -> MAY | C23: 46173 | D23: {=IFERROR(INDEX('Kode Outlet dan Target Toko'!$A:$A,MATCH($I23,'Kode Outlet dan Target Toko'!$E:$E,0)),"")} -> GRSM 4 | E23: =IFERROR(VLOOKUP(I23,KET!$B:$F,4,0),"") -> FAHMI LUKMANUL HAKIM | F23: =IFERROR(VLOOKUP(I23,KET!$B:$F,5,0),"") -> GMM | G23: =IFERROR(INDEX('Kode Outlet dan Target Toko'!$C:$C,MATCH($I23,'Kode Outlet dan Target Toko'!$E:$E,0)),0) -> 103259 | H23: =IFERROR(INDEX('Kode Outlet dan Target Toko'!$D:$D,MATCH($I23,'Kode Outlet dan Target Toko'!$E:$E,0)),0) -> 9029389 | I23: KAIRO | J23: MEGA FITRIA | K23: CARBONARA | L23: 2000 | M23: 63 | N23: =IFERROR(M23*L23,"") -> 126000
A24: 22 | B24: =IF(C24="","",UPPER(TEXT(C24, "MMM"))) -> MAY | C24: 46173 | D24: {=IFERROR(INDEX('Kode Outlet dan Target Toko'!$A:$A,MATCH($I24,'Kode Outlet dan Target Toko'!$E:$E,0)),"")} -> GRSM 4 | E24: =IFERROR(VLOOKUP(I24,KET!$B:$F,4,0),"") -> FAHMI LUKMANUL HAKIM | F24: =IFERROR(VLOOKUP(I24,KET!$B:$F,5,0),"") -> GMM | G24: =IFERROR(INDEX('Kode Outlet dan Target Toko'!$C:$C,MATCH($I24,'Kode Outlet dan Target Toko'!$E:$E,0)),0) -> 103259 | H24: =IFERROR(INDEX('Kode Outlet dan Target Toko'!$D:$D,MATCH($I24,'Kode Outlet dan Target Toko'!$E:$E,0)),0) -> 9029389 | I24: KAIRO | J24: MEGA FITRIA | K24: AGLIO OLIO | L24: 2000 | M24: 36 | N24: =IFERROR(M24*L24,"") -> 72000
A25: 22 | B25: =IF(C25="","",UPPER(TEXT(C25, "MMM"))) -> MAY | C25: 46173 | D25: {=IFERROR(INDEX('Kode Outlet dan Target Toko'!$A:$A,MATCH($I25,'Kode Outlet dan Target Toko'!$E:$E,0)),"")} -> GRSM 4 | E25: =IFERROR(VLOOKUP(I25,KET!$B:$F,4,0),"") -> FAHMI LUKMANUL HAKIM | F25: =IFERROR(VLOOKUP(I25,KET!$B:$F,5,0),"") -> GMM | G25: =IFERROR(INDEX('Kode Outlet dan Target Toko'!$C:$C,MATCH($I25,'Kode Outlet dan Target Toko'!$E:$E,0)),0) -> 103259 | H25: =IFERROR(INDEX('Kode Outlet dan Target Toko'!$D:$D,MATCH($I25,'Kode Outlet dan Target Toko'!$E:$E,0)),0) -> 9029389 | I25: KAIRO | J25: MEGA FITRIA | K25: GORENG | L25: 2000 | M25: 93 | N25: =IFERROR(M25*L25,"") -> 186000
A26: 22 | B26: =IF(C26="","",UPPER(TEXT(C26, "MMM"))) -> MAY | C26: 46173 | D26: {=IFERROR(INDEX('Kode Outlet dan Target Toko'!$A:$A,MATCH($I26,'Kode Outlet dan Target Toko'!$E:$E,0)),"")} -> GRSM 4 | E26: =IFERROR(VLOOKUP(I26,KET!$B:$F,4,0),"") -> FAHMI LUKMANUL HAKIM | F26: =IFERROR(VLOOKUP(I26,KET!$B:$F,5,0),"") -> GMM | G26: =IFERROR(INDEX('Kode Outlet dan Target Toko'!$C:$C,MATCH($I26,'Kode Outlet dan Target Toko'!$E:$E,0)),0) -> 103259 | H26: =IFERROR(INDEX('Kode Outlet dan Target Toko'!$D:$D,MATCH($I26,'Kode Outlet dan Target Toko'!$E:$E,0)),0) -> 9029389 | I26: KAIRO | J26: GINA FITRIANTI NUGRAHA | K26: BOLOGNESE | L26: 2000 | M26: 87 | N26: =IFERROR(M26*L26,"") -> 174000 | O26: 160
A27: 22 | B27: =IF(C27="","",UPPER(TEXT(C27, "MMM"))) -> MAY | C27: 46173 | D27: {=IFERROR(INDEX('Kode Outlet dan Target Toko'!$A:$A,MATCH($I27,'Kode Outlet dan Target Toko'!$E:$E,0)),"")} -> GRSM 4 | E27: =IFERROR(VLOOKUP(I27,KET!$B:$F,4,0),"") -> FAHMI LUKMANUL HAKIM | F27: =IFERROR(VLOOKUP(I27,KET!$B:$F,5,0),"") -> GMM | G27: =IFERROR(INDEX('Kode Outlet dan Target Toko'!$C:$C,MATCH($I27,'Kode Outlet dan Target Toko'!$E:$E,0)),0) -> 103259 | H27: =IFERROR(INDEX('Kode Outlet dan Target Toko'!$D:$D,MATCH($I27,'Kode Outlet dan Target Toko'!$E:$E,0)),0) -> 9029389 | I27: KAIRO | J27: GINA FITRIANTI NUGRAHA | K27: CARBONARA | L27: 2000 | M27: 60 | N27: =IFERROR(M27*L27,"") -> 120000
A28: 22 | B28: =IF(C28="","",UPPER(TEXT(C28, "MMM"))) -> MAY | C28: 46173 | D28: {=IFERROR(INDEX('Kode Outlet dan Target Toko'!$A:$A,MATCH($I28,'Kode Outlet dan Target Toko'!$E:$E,0)),"")} -> GRSM 4 | E28: =IFERROR(VLOOKUP(I28,KET!$B:$F,4,0),"") -> FAHMI LUKMANUL HAKIM | F28: =IFERROR(VLOOKUP(I28,KET!$B:$F,5,0),"") -> GMM | G28: =IFERROR(INDEX('Kode Outlet dan Target Toko'!$C:$C,MATCH($I28,'Kode Outlet dan Target Toko'!$E:$E,0)),0) -> 103259 | H28: =IFERROR(INDEX('Kode Outlet dan Target Toko'!$D:$D,MATCH($I28,'Kode Outlet dan Target Toko'!$E:$E,0)),0) -> 9029389 | I28: KAIRO | J28: GINA FITRIANTI NUGRAHA | K28: AGLIO OLIO | L28: 2000 | M28: 66 | N28: =IFERROR(M28*L28,"") -> 132000
A29: 22 | B29: =IF(C29="","",UPPER(TEXT(C29, "MMM"))) -> MAY | C29: 46173 | D29: {=IFERROR(INDEX('Kode Outlet dan Target Toko'!$A:$A,MATCH($I29,'Kode Outlet dan Target Toko'!$E:$E,0)),"")} -> GRSM 4 | E29: =IFERROR(VLOOKUP(I29,KET!$B:$F,4,0),"") -> FAHMI LUKMANUL HAKIM | F29: =IFERROR(VLOOKUP(I29,KET!$B:$F,5,0),"") -> GMM | G29: =IFERROR(INDEX('Kode Outlet dan Target Toko'!$C:$C,MATCH($I29,'Kode Outlet dan Target Toko'!$E:$E,0)),0) -> 103259 | H29: =IFERROR(INDEX('Kode Outlet dan Target Toko'!$D:$D,MATCH($I29,'Kode Outlet dan Target Toko'!$E:$E,0)),0) -> 9029389 | I29: KAIRO | J29: GINA FITRIANTI NUGRAHA | K29: GORENG | L29: 2000 | M29: 57 | N29: =IFERROR(M29*L29,"") -> 114000
A30: 22 | B30: =IF(C30="","",UPPER(TEXT(C30, "MMM"))) -> MAY | C30: 46173 | D30: {=IFERROR(INDEX('Kode Outlet dan Target Toko'!$A:$A,MATCH($I30,'Kode Outlet dan Target Toko'!$E:$E,0)),"")} -> GRSM 4 | E30: =IFERROR(VLOOKUP(I30,KET!$B:$F,4,0),"") -> FAHMI LUKMANUL HAKIM | F30: =IFERROR(VLOOKUP(I30,KET!$B:$F,5,0),"") -> GMM | G30: =IFERROR(INDEX('Kode Outlet dan Target Toko'!$C:$C,MATCH($I30,'Kode Outlet dan Target Toko'!$E:$E,0)),0) -> 103277 | H30: =IFERROR(INDEX('Kode Outlet dan Target Toko'!$D:$D,MATCH($I30,'Kode Outlet dan Target Toko'!$E:$E,0)),0) -> 6300538 | I30: MITRA INDAH | J30: WINDIANINGSIH | K30: BOLOGNESE | L30: 2975 | M30: 33 | N30: =IFERROR(M30*L30,"") -> 98175 | O30: 160
A31: 22 | B31: =IF(C31="","",UPPER(TEXT(C31, "MMM"))) -> MAY | C31: 46173 | D31: {=IFERROR(INDEX('Kode Outlet dan Target Toko'!$A:$A,MATCH($I31,'Kode Outlet dan Target Toko'!$E:$E,0)),"")} -> GRSM 4 | E31: =IFERROR(VLOOKUP(I31,KET!$B:$F,4,0),"") -> FAHMI LUKMANUL HAKIM | F31: =IFERROR(VLOOKUP(I31,KET!$B:$F,5,0),"") -> GMM | G31: =IFERROR(INDEX('Kode Outlet dan Target Toko'!$C:$C,MATCH($I31,'Kode Outlet dan Target Toko'!$E:$E,0)),0) -> 103277 | H31: =IFERROR(INDEX('Kode Outlet dan Target Toko'!$D:$D,MATCH($I31,'Kode Outlet dan Target Toko'!$E:$E,0)),0) -> 6300538 | I31: MITRA INDAH | J31: WINDIANINGSIH | K31: CARBONARA | L31: 2975 | M31: 88 | N31: =IFERROR(M31*L31,"") -> 261800
A32: 22 | B32: =IF(C32="","",UPPER(TEXT(C32, "MMM"))) -> MAY | C32: 46173 | D32: {=IFERROR(INDEX('Kode Outlet dan Target Toko'!$A:$A,MATCH($I32,'Kode Outlet dan Target Toko'!$E:$E,0)),"")} -> GRSM 4 | E32: =IFERROR(VLOOKUP(I32,KET!$B:$F,4,0),"") -> FAHMI LUKMANUL HAKIM | F32: =IFERROR(VLOOKUP(I32,KET!$B:$F,5,0),"") -> GMM | G32: =IFERROR(INDEX('Kode Outlet dan Target Toko'!$C:$C,MATCH($I32,'Kode Outlet dan Target Toko'!$E:$E,0)),0) -> 103277 | H32: =IFERROR(INDEX('Kode Outlet dan Target Toko'!$D:$D,MATCH($I32,'Kode Outlet dan Target Toko'!$E:$E,0)),0) -> 6300538 | I32: MITRA INDAH | J32: WINDIANINGSIH | K32: AGLIO OLIO | L32: 2975 | M32: 60 | N32: =IFERROR(M32*L32,"") -> 178500
A33: 22 | B33: =IF(C33="","",UPPER(TEXT(C33, "MMM"))) -> MAY | C33: 46173 | D33: {=IFERROR(INDEX('Kode Outlet dan Target Toko'!$A:$A,MATCH($I33,'Kode Outlet dan Target Toko'!$E:$E,0)),"")} -> GRSM 4 | E33: =IFERROR(VLOOKUP(I33,KET!$B:$F,4,0),"") -> FAHMI LUKMANUL HAKIM | F33: =IFERROR(VLOOKUP(I33,KET!$B:$F,5,0),"") -> GMM | G33: =IFERROR(INDEX('Kode Outlet dan Target Toko'!$C:$C,MATCH($I33,'Kode Outlet dan Target Toko'!$E:$E,0)),0) -> 103277 | H33: =IFERROR(INDEX('Kode Outlet dan Target Toko'!$D:$D,MATCH($I33,'Kode Outlet dan Target Toko'!$E:$E,0)),0) -> 6300538 | I33: MITRA INDAH | J33: WINDIANINGSIH | K33: GORENG | L33: 2975 | M33: 149 | N33: =IFERROR(M33*L33,"") -> 443275
A34: 22 | B34: =IF(C34="","",UPPER(TEXT(C34, "MMM"))) -> MAY | C34: 46173 | D34: {=IFERROR(INDEX('Kode Outlet dan Target Toko'!$A:$A,MATCH($I34,'Kode Outlet dan Target Toko'!$E:$E,0)),"")} -> GRSM 4 | E34: =IFERROR(VLOOKUP(I34,KET!$B:$F,4,0),"") -> FAHMI LUKMANUL HAKIM | F34: =IFERROR(VLOOKUP(I34,KET!$B:$F,5,0),"") -> GMM | G34: =IFERROR(INDEX('Kode Outlet dan Target Toko'!$C:$C,MATCH($I34,'Kode Outlet dan Target Toko'!$E:$E,0)),0) -> 103277 | H34: =IFERROR(INDEX('Kode Outlet dan Target Toko'!$D:$D,MATCH($I34,'Kode Outlet dan Target Toko'!$E:$E,0)),0) -> 6300538 | I34: MITRA INDAH | J34: NURMALA RUSTAMALIA | K34: BOLOGNESE | L34: 2975 | M34: 29 | N34: =IFERROR(M34*L34,"") -> 86275 | O34: 147
A35: 22 | B35: =IF(C35="","",UPPER(TEXT(C35, "MMM"))) -> MAY | C35: 46173 | D35: {=IFERROR(INDEX('Kode Outlet dan Target Toko'!$A:$A,MATCH($I35,'Kode Outlet dan Target Toko'!$E:$E,0)),"")} -> GRSM 4 | E35: =IFERROR(VLOOKUP(I35,KET!$B:$F,4,0),"") -> FAHMI LUKMANUL HAKIM | F35: =IFERROR(VLOOKUP(I35,KET!$B:$F,5,0),"") -> GMM | G35: =IFERROR(INDEX('Kode Outlet dan Target Toko'!$C:$C,MATCH($I35,'Kode Outlet dan Target Toko'!$E:$E,0)),0) -> 103277 | H35: =IFERROR(INDEX('Kode Outlet dan Target Toko'!$D:$D,MATCH($I35,'Kode Outlet dan Target Toko'!$E:$E,0)),0) -> 6300538 | I35: MITRA INDAH | J35: NURMALA RUSTAMALIA | K35: CARBONARA | L35: 2975 | M35: 81 | N35: =IFERROR(M35*L35,"") -> 240975
A36: 22 | B36: =IF(C36="","",UPPER(TEXT(C36, "MMM"))) -> MAY | C36: 46173 | D36: {=IFERROR(INDEX('Kode Outlet dan Target Toko'!$A:$A,MATCH($I36,'Kode Outlet dan Target Toko'!$E:$E,0)),"")} -> GRSM 4 | E36: =IFERROR(VLOOKUP(I36,KET!$B:$F,4,0),"") -> FAHMI LUKMANUL HAKIM | F36: =IFERROR(VLOOKUP(I36,KET!$B:$F,5,0),"") -> GMM | G36: =IFERROR(INDEX('Kode Outlet dan Target Toko'!$C:$C,MATCH($I36,'Kode Outlet dan Target Toko'!$E:$E,0)),0) -> 103277 | H36: =IFERROR(INDEX('Kode Outlet dan Target Toko'!$D:$D,MATCH($I36,'Kode Outlet dan Target Toko'!$E:$E,0)),0) -> 6300538 | I36: MITRA INDAH | J36: NURMALA RUSTAMALIA | K36: AGLIO OLIO | L36: 2975 | M36: 47 | N36: =IFERROR(M36*L36,"") -> 139825
A37: 22 | B37: =IF(C37="","",UPPER(TEXT(C37, "MMM"))) -> MAY | C37: 46173 | D37: {=IFERROR(INDEX('Kode Outlet dan Target Toko'!$A:$A,MATCH($I37,'Kode Outlet dan Target Toko'!$E:$E,0)),"")} -> GRSM 4 | E37: =IFERROR(VLOOKUP(I37,KET!$B:$F,4,0),"") -> FAHMI LUKMANUL HAKIM | F37: =IFERROR(VLOOKUP(I37,KET!$B:$F,5,0),"") -> GMM | G37: =IFERROR(INDEX('Kode Outlet dan Target Toko'!$C:$C,MATCH($I37,'Kode Outlet dan Target Toko'!$E:$E,0)),0) -> 103277 | H37: =IFERROR(INDEX('Kode Outlet dan Target Toko'!$D:$D,MATCH($I37,'Kode Outlet dan Target Toko'!$E:$E,0)),0) -> 6300538 | I37: MITRA INDAH | J37: NURMALA RUSTAMALIA | K37: GORENG | L37: 2975 | M37: 151 | N37: =IFERROR(M37*L37,"") -> 449225
A38: 22 | B38: =IF(C38="","",UPPER(TEXT(C38, "MMM"))) -> MAY | C38: 46173 | D38: {=IFERROR(INDEX('Kode Outlet dan Target Toko'!$A:$A,MATCH($I38,'Kode Outlet dan Target Toko'!$E:$E,0)),"")} -> GRSM 4 | E38: =IFERROR(VLOOKUP(I38,KET!$B:$F,4,0),"") -> FAHMI LUKMANUL HAKIM | F38: =IFERROR(VLOOKUP(I38,KET!$B:$F,5,0),"") -> GMM | G38: =IFERROR(INDEX('Kode Outlet dan Target Toko'!$C:$C,MATCH($I38,'Kode Outlet dan Target Toko'!$E:$E,0)),0) -> 189901 | H38: =IFERROR(INDEX('Kode Outlet dan Target Toko'!$D:$D,MATCH($I38,'Kode Outlet dan Target Toko'!$E:$E,0)),0) -> 1602020 | I38: YOGYA CIAMIS * | J38: YUNIATI | K38: BOLOGNESE | L38: 2200 | M38: 65 | N38: =IFERROR(M38*L38,"") -> 143000 | O38: 147
A39: 22 | B39: =IF(C39="","",UPPER(TEXT(C39, "MMM"))) -> MAY | C39: 46173 | D39: {=IFERROR(INDEX('Kode Outlet dan Target Toko'!$A:$A,MATCH($I39,'Kode Outlet dan Target Toko'!$E:$E,0)),"")} -> GRSM 4 | E39: =IFERROR(VLOOKUP(I39,KET!$B:$F,4,0),"") -> FAHMI LUKMANUL HAKIM | F39: =IFERROR(VLOOKUP(I39,KET!$B:$F,5,0),"") -> GMM | G39: =IFERROR(INDEX('Kode Outlet dan Target Toko'!$C:$C,MATCH($I39,'Kode Outlet dan Target Toko'!$E:$E,0)),0) -> 189901 | H39: =IFERROR(INDEX('Kode Outlet dan Target Toko'!$D:$D,MATCH($I39,'Kode Outlet dan Target Toko'!$E:$E,0)),0) -> 1602020 | I39: YOGYA CIAMIS * | J39: YUNIATI | K39: CARBONARA | L39: 2200 | M39: 136 | N39: =IFERROR(M39*L39,"") -> 299200
A40: 22 | B40: =IF(C40="","",UPPER(TEXT(C40, "MMM"))) -> MAY | C40: 46173 | D40: {=IFERROR(INDEX('Kode Outlet dan Target Toko'!$A:$A,MATCH($I40,'Kode Outlet dan Target Toko'!$E:$E,0)),"")} -> GRSM 4 | E40: =IFERROR(VLOOKUP(I40,KET!$B:$F,4,0),"") -> FAHMI LUKMANUL HAKIM | F40: =IFERROR(VLOOKUP(I40,KET!$B:$F,5,0),"") -> GMM | G40: =IFERROR(INDEX('Kode Outlet dan Target Toko'!$C:$C,MATCH($I40,'Kode Outlet dan Target Toko'!$E:$E,0)),0) -> 189901 | H40: =IFERROR(INDEX('Kode Outlet dan Target Toko'!$D:$D,MATCH($I40,'Kode Outlet dan Target Toko'!$E:$E,0)),0) -> 1602020 | I40: YOGYA CIAMIS * | J40: YUNIATI | K40: AGLIO OLIO | L40: 2200 | M40: 42 | N40: =IFERROR(M40*L40,"") -> 92400
A41: 22 | B41: =IF(C41="","",UPPER(TEXT(C41, "MMM"))) -> MAY | C41: 46173 | D41: {=IFERROR(INDEX('Kode Outlet dan Target Toko'!$A:$A,MATCH($I41,'Kode Outlet dan Target Toko'!$E:$E,0)),"")} -> GRSM 4 | E41: =IFERROR(VLOOKUP(I41,KET!$B:$F,4,0),"") -> FAHMI LUKMANUL HAKIM | F41: =IFERROR(VLOOKUP(I41,KET!$B:$F,5,0),"") -> GMM | G41: =IFERROR(INDEX('Kode Outlet dan Target Toko'!$C:$C,MATCH($I41,'Kode Outlet dan Target Toko'!$E:$E,0)),0) -> 189901 | H41: =IFERROR(INDEX('Kode Outlet dan Target Toko'!$D:$D,MATCH($I41,'Kode Outlet dan Target Toko'!$E:$E,0)),0) -> 1602020 | I41: YOGYA CIAMIS * | J41: HANNA AFTINA LISTYANI | K41: BOLOGNESE | L41: 2200 | M41: 63 | N41: =IFERROR(M41*L41,"") -> 138600 | O41: 120
A42: 22 | B42: =IF(C42="","",UPPER(TEXT(C42, "MMM"))) -> MAY | C42: 46173 | D42: {=IFERROR(INDEX('Kode Outlet dan Target Toko'!$A:$A,MATCH($I42,'Kode Outlet dan Target Toko'!$E:$E,0)),"")} -> GRSM 4 | E42: =IFERROR(VLOOKUP(I42,KET!$B:$F,4,0),"") -> FAHMI LUKMANUL HAKIM | F42: =IFERROR(VLOOKUP(I42,KET!$B:$F,5,0),"") -> GMM | G42: =IFERROR(INDEX('Kode Outlet dan Target Toko'!$C:$C,MATCH($I42,'Kode Outlet dan Target Toko'!$E:$E,0)),0) -> 189901 | H42: =IFERROR(INDEX('Kode Outlet dan Target Toko'!$D:$D,MATCH($I42,'Kode Outlet dan Target Toko'!$E:$E,0)),0) -> 1602020 | I42: YOGYA CIAMIS * | J42: HANNA AFTINA LISTYANI | K42: CARBONARA | L42: 2200 | M42: 141 | N42: =IFERROR(M42*L42,"") -> 310200
...

Sheet MONITORING STOK
A1: REPORT MONITORING STOK GMM WOW SPAGHETTI JAWA BARAT
A2: *Pengisian dengan huruf CAPITAL | G2: : Jangan copas/edit ke tanda berwarna ini! | H2: : Jangan copas/edit ke tanda berwarna ini!
A5: WEEK | B5: BULAN | C5: TANGGAL | D5: GRSM | E5: AREA | F5: NAMA TL | G5: CHANNEL GROUP | H5: NAMA TOKO | I5: STOK AWAL (IN PCS) | N5: STOK AKHIR (IN PCS)
I6: AGLIO OLIO | J6: CARBONARA | K6: BOLOGNESE | L6: GORENG | M6: TOTAL (ALL VARIAN) | N6: AGLIO OLIO | O6: CARBONARA | P6: BOLOGNESE | Q6: GORENG | R6: TOTAL (ALL VARIAN)
A7: 22 | B7: =IF(C7="","",UPPER(TEXT(C7, "MMM"))) -> MAY | C7: 46171 | D7: =IFERROR(VLOOKUP(H7,KET!$B:$F,2,0),"") -> GRSM 4 | E7: =IFERROR(VLOOKUP(H7,KET!$B:$F,3,0),"") -> TASIK | F7: =IFERROR(VLOOKUP(H7,KET!$B:$F,4,0),"") -> FAHMI LUKMANUL HAKIM | G7: =IFERROR(VLOOKUP(H7,KET!$B:$F,5,0),"") -> GMM | H7: KAIRO | I7: 969 | J7: 1099 | K7: 825 | L7: 666 | M7: =SUM(I7:L7) -> 3559 | N7: 942 | O7: 1036 | P7: 771 | Q7: 477 | R7: =SUM(N7:Q7) -> 3226
A8: 22 | B8: =IF(C8="","",UPPER(TEXT(C8, "MMM"))) -> MAY | C8: 46171 | D8: =IFERROR(VLOOKUP(H8,KET!$B:$F,2,0),"") -> GRSM 4 | E8: =IFERROR(VLOOKUP(H8,KET!$B:$F,3,0),"") -> TASIK | F8: =IFERROR(VLOOKUP(H8,KET!$B:$F,4,0),"") -> FAHMI LUKMANUL HAKIM | G8: =IFERROR(VLOOKUP(H8,KET!$B:$F,5,0),"") -> GMM | H8: KAIRO | I8: 1008 | J8: 1153 | K8: 876 | L8: 795 | M8: =SUM(I8:L8) -> 3832 | N8: 969 | O8: 1099 | P8: 825 | Q8: 666 | R8: =SUM(N8:Q8) -> 3559
A9: 22 | B9: =IF(C9="","",UPPER(TEXT(C9, "MMM"))) -> MAY | C9: 46172 | D9: =IFERROR(VLOOKUP(H9,KET!$B:$F,2,0),"") -> GRSM 4 | E9: =IFERROR(VLOOKUP(H9,KET!$B:$F,3,0),"") -> TASIK | F9: =IFERROR(VLOOKUP(H9,KET!$B:$F,4,0),"") -> FAHMI LUKMANUL HAKIM | G9: =IFERROR(VLOOKUP(H9,KET!$B:$F,5,0),"") -> GMM | H9: KAIRO | I9: 889 | J9: 967 | K9: 690 | L9: 405 | M9: =SUM(I9:L9) -> 2951 | N9: 835 | O9: 883 | P9: 615 | Q9: 315 | R9: =SUM(N9:Q9) -> 2648
A10: 22 | B10: =IF(C10="","",UPPER(TEXT(C10, "MMM"))) -> MAY | C10: 46172 | D10: =IFERROR(VLOOKUP(H10,KET!$B:$F,2,0),"") -> GRSM 4 | E10: =IFERROR(VLOOKUP(H10,KET!$B:$F,3,0),"") -> TASIK | F10: =IFERROR(VLOOKUP(H10,KET!$B:$F,4,0),"") -> FAHMI LUKMANUL HAKIM | G10: =IFERROR(VLOOKUP(H10,KET!$B:$F,5,0),"") -> GMM | H10: KAIRO | I10: 942 | J10: 1036 | K10: 771 | L10: 477 | M10: =SUM(I10:L10) -> 3226 | N10: 889 | O10: 967 | P10: 690 | Q10: 405 | R10: =SUM(N10:Q10) -> 2951
A11: 22 | B11: =IF(C11="","",UPPER(TEXT(C11, "MMM"))) -> MAY | C11: 46173 | D11: =IFERROR(VLOOKUP(H11,KET!$B:$F,2,0),"") -> GRSM 4 | E11: =IFERROR(VLOOKUP(H11,KET!$B:$F,3,0),"") -> TASIK | F11: =IFERROR(VLOOKUP(H11,KET!$B:$F,4,0),"") -> FAHMI LUKMANUL HAKIM | G11: =IFERROR(VLOOKUP(H11,KET!$B:$F,5,0),"") -> GMM | H11: KAIRO | I11: 835 | J11: 883 | K11: 615 | L11: 315 | M11: =SUM(I11:L11) -> 2648 | N11: 799 | O11: 757 | P11: 471 | Q11: 222 | R11: =SUM(N11:Q11) -> 2249
A12: 22 | B12: =IF(C12="","",UPPER(TEXT(C12, "MMM"))) -> MAY | C12: 46173 | D12: =IFERROR(VLOOKUP(H12,KET!$B:$F,2,0),"") -> GRSM 4 | E12: =IFERROR(VLOOKUP(H12,KET!$B:$F,3,0),"") -> TASIK | F12: =IFERROR(VLOOKUP(H12,KET!$B:$F,4,0),"") -> FAHMI LUKMANUL HAKIM | G12: =IFERROR(VLOOKUP(H12,KET!$B:$F,5,0),"") -> GMM | H12: KAIRO | I12: 799 | J12: 757 | K12: 471 | L12: 222 | M12: =SUM(I12:L12) -> 2249 | N12: 742 | O12: 697 | P12: 384 | Q12: 165 | R12: =SUM(N12:Q12) -> 1988
A13: 22 | B13: =IF(C13="","",UPPER(TEXT(C13, "MMM"))) -> MAY | C13: 46171 | D13: =IFERROR(VLOOKUP(H13,KET!$B:$F,2,0),"") -> GRSM 4 | E13: =IFERROR(VLOOKUP(H13,KET!$B:$F,3,0),"") -> KUNINGAN | F13: =IFERROR(VLOOKUP(H13,KET!$B:$F,4,0),"") -> FAHMI LUKMANUL HAKIM | G13: =IFERROR(VLOOKUP(H13,KET!$B:$F,5,0),"") -> GMM | H13: MITRA INDAH | I13: 582 | J13: 688 | K13: 1032 | L13: 3357 | M13: =SUM(I13:L13) -> 5659 | N13: 519 | O13: 627 | P13: 99 | Q13: 3283 | R13: =SUM(N13:Q13) -> 4528
A14: 22 | B14: =IF(C14="","",UPPER(TEXT(C14, "MMM"))) -> MAY | C14: 46171 | D14: =IFERROR(VLOOKUP(H14,KET!$B:$F,2,0),"") -> GRSM 4 | E14: =IFERROR(VLOOKUP(H14,KET!$B:$F,3,0),"") -> KUNINGAN | F14: =IFERROR(VLOOKUP(H14,KET!$B:$F,4,0),"") -> FAHMI LUKMANUL HAKIM | G14: =IFERROR(VLOOKUP(H14,KET!$B:$F,5,0),"") -> GMM | H14: MITRA INDAH | I14: 582 | J14: 688 | K14: 1032 | L14: 3357 | M14: =SUM(I14:L14) -> 5659 | N14: 486 | O14: 564 | P14: 938 | Q14: 3199 | R14: =SUM(N14:Q14) -> 5187
A15: 22 | B15: =IF(C15="","",UPPER(TEXT(C15, "MMM"))) -> MAY | C15: 46172 | D15: =IFERROR(VLOOKUP(H15,KET!$B:$F,2,0),"") -> GRSM 4 | E15: =IFERROR(VLOOKUP(H15,KET!$B:$F,3,0),"") -> KUNINGAN | F15: =IFERROR(VLOOKUP(H15,KET!$B:$F,4,0),"") -> FAHMI LUKMANUL HAKIM | G15: =IFERROR(VLOOKUP(H15,KET!$B:$F,5,0),"") -> GMM | H15: MITRA INDAH | I15: 486 | J15: 564 | K15: 938 | L15: 3199 | M15: =SUM(I15:L15) -> 5187 | N15: 429 | O15: 488 | P15: 909 | Q15: 3072 | R15: =SUM(N15:Q15) -> 4898
A16: 22 | B16: =IF(C16="","",UPPER(TEXT(C16, "MMM"))) -> MAY | C16: 46172 | D16: =IFERROR(VLOOKUP(H16,KET!$B:$F,2,0),"") -> GRSM 4 | E16: =IFERROR(VLOOKUP(H16,KET!$B:$F,3,0),"") -> KUNINGAN | F16: =IFERROR(VLOOKUP(H16,KET!$B:$F,4,0),"") -> FAHMI LUKMANUL HAKIM | G16: =IFERROR(VLOOKUP(H16,KET!$B:$F,5,0),"") -> GMM | H16: MITRA INDAH | I16: 486 | J16: 564 | K16: 938 | L16: 3199 | M16: =SUM(I16:L16) -> 5187 | N16: 386 | O16: 414 | P16: 885 | Q16: 2941 | R16: =SUM(N16:Q16) -> 4626
A17: 22 | B17: =IF(C17="","",UPPER(TEXT(C17, "MMM"))) -> MAY | C17: 46173 | D17: =IFERROR(VLOOKUP(H17,KET!$B:$F,2,0),"") -> GRSM 4 | E17: =IFERROR(VLOOKUP(H17,KET!$B:$F,3,0),"") -> KUNINGAN | F17: =IFERROR(VLOOKUP(H17,KET!$B:$F,4,0),"") -> FAHMI LUKMANUL HAKIM | G17: =IFERROR(VLOOKUP(H17,KET!$B:$F,5,0),"") -> GMM | H17: MITRA INDAH | I17: 386 | J17: 414 | K17: 885 | L17: 2941 | M17: =SUM(I17:L17) -> 4626 | N17: 326 | O17: 326 | P17: 852 | Q17: 2792 | R17: =SUM(N17:Q17) -> 4296
A18: 22 | B18: =IF(C18="","",UPPER(TEXT(C18, "MMM"))) -> MAY | C18: 46173 | D18: =IFERROR(VLOOKUP(H18,KET!$B:$F,2,0),"") -> GRSM 4 | E18: =IFERROR(VLOOKUP(H18,KET!$B:$F,3,0),"") -> KUNINGAN | F18: =IFERROR(VLOOKUP(H18,KET!$B:$F,4,0),"") -> FAHMI LUKMANUL HAKIM | G18: =IFERROR(VLOOKUP(H18,KET!$B:$F,5,0),"") -> GMM | H18: MITRA INDAH | I18: 386 | J18: 414 | K18: 885 | L18: 2941 | M18: =SUM(I18:L18) -> 4626 | N18: 279 | O18: 245 | P18: 823 | Q18: 2641 | R18: =SUM(N18:Q18) -> 3988
A19: 22 | B19: =IF(C19="","",UPPER(TEXT(C19, "MMM"))) -> MAY | C19: 46171 | D19: =IFERROR(VLOOKUP(H19,KET!$B:$F,2,0),"") -> GRSM 4 | E19: =IFERROR(VLOOKUP(H19,KET!$B:$F,3,0),"") -> TASIK | F19: =IFERROR(VLOOKUP(H19,KET!$B:$F,4,0),"") -> FAHMI LUKMANUL HAKIM | G19: =IFERROR(VLOOKUP(H19,KET!$B:$F,5,0),"") -> GMM | H19: YOGYA CIAMIS * | I19: 818 | J19: 1238 | K19: 1032 | L19: - | M19: =SUM(I19:L19) -> 3088 | N19: 770 | O19: 1175 | P19: 978 | Q19: - | R19: =SUM(N19:Q19) -> 2923
A20: 22 | B20: =IF(C20="","",UPPER(TEXT(C20, "MMM"))) -> MAY | C20: 46171 | D20: =IFERROR(VLOOKUP(H20,KET!$B:$F,2,0),"") -> GRSM 4 | E20: =IFERROR(VLOOKUP(H20,KET!$B:$F,3,0),"") -> TASIK | F20: =IFERROR(VLOOKUP(H20,KET!$B:$F,4,0),"") -> FAHMI LUKMANUL HAKIM | G20: =IFERROR(VLOOKUP(H20,KET!$B:$F,5,0),"") -> GMM | H20: YOGYA CIAMIS * | I20: 818 | J20: 1238 | K20: 1032 | L20: - | M20: =SUM(I20:L20) -> 3088 | N20: 776 | O20: 1121 | P20: 975 | Q20: - | R20: =SUM(N20:Q20) -> 2872
A21: 22 | B21: =IF(C21="","",UPPER(TEXT(C21, "MMM"))) -> MAY | C21: 46172 | D21: =IFERROR(VLOOKUP(H21,KET!$B:$F,2,0),"") -> GRSM 4 | E21: =IFERROR(VLOOKUP(H21,KET!$B:$F,3,0),"") -> TASIK | F21: =IFERROR(VLOOKUP(H21,KET!$B:$F,4,0),"") -> FAHMI LUKMANUL HAKIM | G21: =IFERROR(VLOOKUP(H21,KET!$B:$F,5,0),"") -> GMM | H21: YOGYA CIAMIS * | I21: 776 | J21: 1137 | K21: 975 | L21: - | M21: =SUM(I21:L21) -> 2888 | N21: 689 | O21: 989 | P21: 905 | Q21: - | R21: =SUM(N21:Q21) -> 2583
A22: 22 | B22: =IF(C22="","",UPPER(TEXT(C22, "MMM"))) -> MAY | C22: 46172 | D22: =IFERROR(VLOOKUP(H22,KET!$B:$F,2,0),"") -> GRSM 4 | E22: =IFERROR(VLOOKUP(H22,KET!$B:$F,3,0),"") -> TASIK | F22: =IFERROR(VLOOKUP(H22,KET!$B:$F,4,0),"") -> FAHMI LUKMANUL HAKIM | G22: =IFERROR(VLOOKUP(H22,KET!$B:$F,5,0),"") -> GMM | H22: YOGYA CIAMIS * | I22: 776 | J22: 1137 | K22: 975 | L22: - | M22: =SUM(I22:L22) -> 2888 | N22: 702 | O22: 983 | P22: 895 | Q22: - | R22: =SUM(N22:Q22) -> 2580
A23: 22 | B23: =IF(C23="","",UPPER(TEXT(C23, "MMM"))) -> MAY | C23: 46173 | D23: =IFERROR(VLOOKUP(H23,KET!$B:$F,2,0),"") -> GRSM 4 | E23: =IFERROR(VLOOKUP(H23,KET!$B:$F,3,0),"") -> TASIK | F23: =IFERROR(VLOOKUP(H23,KET!$B:$F,4,0),"") -> FAHMI LUKMANUL HAKIM | G23: =IFERROR(VLOOKUP(H23,KET!$B:$F,5,0),"") -> GMM | H23: YOGYA CIAMIS * | I23: 666 | J23: 842 | K23: 832 | L23: - | M23: =SUM(I23:L23) -> 2340 | N23: 624 | O23: 706 | P23: 767 | Q23: - | R23: =SUM(N23:Q23) -> 2097
A24: 22 | B24: =IF(C24="","",UPPER(TEXT(C24, "MMM"))) -> MAY | C24: 46173 | D24: =IFERROR(VLOOKUP(H24,KET!$B:$F,2,0),"") -> GRSM 4 | E24: =IFERROR(VLOOKUP(H24,KET!$B:$F,3,0),"") -> TASIK | F24: =IFERROR(VLOOKUP(H24,KET!$B:$F,4,0),"") -> FAHMI LUKMANUL HAKIM | G24: =IFERROR(VLOOKUP(H24,KET!$B:$F,5,0),"") -> GMM | H24: YOGYA CIAMIS * | I24: 702 | J24: 983 | K24: 895 | L24: - | M24: =SUM(I24:L24) -> 2580 | N24: 666 | O24: 842 | P24: 832 | Q24: - | R24: =SUM(N24:Q24) -> 2340
A25: 23 | B25: =IF(C25="","",UPPER(TEXT(C25, "MMM"))) -> JUN | C25: 46178 | D25: =IFERROR(VLOOKUP(H25,KET!$B:$F,2,0),"") -> GRSM 4 | E25: =IFERROR(VLOOKUP(H25,KET!$B:$F,3,0),"") -> TASIK | F25: =IFERROR(VLOOKUP(H25,KET!$B:$F,4,0),"") -> FAHMI LUKMANUL HAKIM | G25: =IFERROR(VLOOKUP(H25,KET!$B:$F,5,0),"") -> GMM | H25: KAIRO | I25: 1083 | J25: 1440 | K25: 1413 | L25: 1014 | M25: =SUM(I25:L25) -> 4950 | N25: 1053 | O25: 1374 | P25: 1356 | Q25: 954 | R25: =SUM(N25:Q25) -> 4737
A26: 23 | B26: =IF(C26="","",UPPER(TEXT(C26, "MMM"))) -> JUN | C26: 46178 | D26: =IFERROR(VLOOKUP(H26,KET!$B:$F,2,0),"") -> GRSM 4 | E26: =IFERROR(VLOOKUP(H26,KET!$B:$F,3,0),"") -> TASIK | F26: =IFERROR(VLOOKUP(H26,KET!$B:$F,4,0),"") -> FAHMI LUKMANUL HAKIM | G26: =IFERROR(VLOOKUP(H26,KET!$B:$F,5,0),"") -> GMM | H26: KAIRO | I26: 1053 | J26: 1474 | K26: 1356 | L26: 954 | M26: =SUM(I26:L26) -> 4837 | N26: 1023 | O26: 1320 | P26: 1293 | Q26: 834 | R26: =SUM(N26:Q26) -> 4470
A27: 23 | B27: =IF(C27="","",UPPER(TEXT(C27, "MMM"))) -> JUN | C27: 46178 | D27: =IFERROR(VLOOKUP(H27,KET!$B:$F,2,0),"") -> GRSM 3A | E27: =IFERROR(VLOOKUP(H27,KET!$B:$F,3,0),"") -> SUKABUMI | F27: =IFERROR(VLOOKUP(H27,KET!$B:$F,4,0),"") -> FAHMI LUKMANUL HAKIM | G27: =IFERROR(VLOOKUP(H27,KET!$B:$F,5,0),"") -> GMM | H27: MULTI GROSIR STASIUN | I27: 553 | J27: 1030 | K27: 682 | L27: 906 | M27: =SUM(I27:L27) -> 3171 | N27: 1053 | O27: 1374 | P27: 669 | Q27: 861 | R27: =SUM(N27:Q27) -> 3957
A28: 23 | B28: =IF(C28="","",UPPER(TEXT(C28, "MMM"))) -> JUN | C28: 46178 | D28: =IFERROR(VLOOKUP(H28,KET!$B:$F,2,0),"") -> GRSM 4 | E28: =IFERROR(VLOOKUP(H28,KET!$B:$F,3,0),"") -> KUNINGAN | F28: =IFERROR(VLOOKUP(H28,KET!$B:$F,4,0),"") -> FAHMI LUKMANUL HAKIM | G28: =IFERROR(VLOOKUP(H28,KET!$B:$F,5,0),"") -> GMM | H28: MITRA INDAH | I28: 279 | J28: 245 | K28: 823 | L28: 2641 | M28: =SUM(I28:L28) -> 3988 | N28: 189 | O28: 131 | P28: 716 | Q28: 2329 | R28: =SUM(N28:Q28) -> 3365
A29: 23 | B29: =IF(C29="","",UPPER(TEXT(C29, "MMM"))) -> JUN | C29: 46178 | D29: =IFERROR(VLOOKUP(H29,KET!$B:$F,2,0),"") -> GRSM 4 | E29: =IFERROR(VLOOKUP(H29,KET!$B:$F,3,0),"") -> KUNINGAN | F29: =IFERROR(VLOOKUP(H29,KET!$B:$F,4,0),"") -> FAHMI LUKMANUL HAKIM | G29: =IFERROR(VLOOKUP(H29,KET!$B:$F,5,0),"") -> GMM | H29: MITRA INDAH | I29: 279 | J29: 245 | K29: 823 | L29: 2641 | M29: =SUM(I29:L29) -> 3988 | N29: 228 | O29: 172 | P29: 766 | Q29: 2476 | R29: =SUM(N29:Q29) -> 3642
A30: 23 | B30: =IF(C30="","",UPPER(TEXT(C30, "MMM"))) -> JUN | C30: 46178 | D30: =IFERROR(VLOOKUP(H30,KET!$B:$F,2,0),"") -> GRSM 4 | E30: =IFERROR(VLOOKUP(H30,KET!$B:$F,3,0),"") -> GARUT | F30: =IFERROR(VLOOKUP(H30,KET!$B:$F,4,0),"") -> FAHMI LUKMANUL HAKIM | G30: =IFERROR(VLOOKUP(H30,KET!$B:$F,5,0),"") -> GMM | H30: PRATAMA PUTRA BANYURESMI | I30: 280 | J30: 450 | K30: 480 | L30: 2280 | M30: =SUM(I30:L30) -> 3490 | N30: 250 | O30: 415 | P30: 440 | Q30: 2175 | R30: =SUM(N30:Q30) -> 3280
A31: 23 | B31: =IF(C31="","",UPPER(TEXT(C31, "MMM"))) -> JUN | C31: 46178 | D31: =IFERROR(VLOOKUP(H31,KET!$B:$F,2,0),"") -> GRSM 4 | E31: =IFERROR(VLOOKUP(H31,KET!$B:$F,3,0),"") -> GARUT | F31: =IFERROR(VLOOKUP(H31,KET!$B:$F,4,0),"") -> FAHMI LUKMANUL HAKIM | G31: =IFERROR(VLOOKUP(H31,KET!$B:$F,5,0),"") -> GMM | H31: PRATAMA PUTRA BANYURESMI | I31: 280 | J31: 450 | K31: 480 | L31: 2280 | M31: =SUM(I31:L31) -> 3490 | N31: 255 | O31: 420 | P31: 445 | Q31: 2180 | R31: =SUM(N31:Q31) -> 3300
A32: 23 | B32: =IF(C32="","",UPPER(TEXT(C32, "MMM"))) -> JUN | C32: 46178 | D32: =IFERROR(VLOOKUP(H32,KET!$B:$F,2,0),"") -> GRSM 4 | E32: =IFERROR(VLOOKUP(H32,KET!$B:$F,3,0),"") -> TASIK | F32: =IFERROR(VLOOKUP(H32,KET!$B:$F,4,0),"") -> FAHMI LUKMANUL HAKIM | G32: =IFERROR(VLOOKUP(H32,KET!$B:$F,5,0),"") -> GMM | H32: M ZAMZAM TK (M2) | I32: 120 | J32: 110 | K32: 120 | L32: 144 | M32: =SUM(I32:L32) -> 494 | N32: 1080 | O32: 2250 | P32: 1362 | Q32: 3900 | R32: =SUM(N32:Q32) -> 8592
A33: 23 | B33: =IF(C33="","",UPPER(TEXT(C33, "MMM"))) -> JUN | C33: 46179 | D33: =IFERROR(VLOOKUP(H33,KET!$B:$F,2,0),"") -> GRSM 4 | E33: =IFERROR(VLOOKUP(H33,KET!$B:$F,3,0),"") -> TASIK | F33: =IFERROR(VLOOKUP(H33,KET!$B:$F,4,0),"") -> FAHMI LUKMANUL HAKIM | G33: =IFERROR(VLOOKUP(H33,KET!$B:$F,5,0),"") -> GMM | H33: M ZAMZAM TK (M2) | I33: 1080 | J33: 2250 | K33: 1362 | L33: 3900 | M33: =SUM(I33:L33) -> 8592 | N33: 960 | O33: 2110 | P33: 1222 | Q33: 3684 | R33: =SUM(N33:Q33) -> 7976
A34: 23 | B34: =IF(C34="","",UPPER(TEXT(C34, "MMM"))) -> JUN | C34: 46179 | D34: =IFERROR(VLOOKUP(H34,KET!$B:$F,2,0),"") -> GRSM 4 | E34: =IFERROR(VLOOKUP(H34,KET!$B:$F,3,0),"") -> TASIK | F34: =IFERROR(VLOOKUP(H34,KET!$B:$F,4,0),"") -> FAHMI LUKMANUL HAKIM | G34: =IFERROR(VLOOKUP(H34,KET!$B:$F,5,0),"") -> GMM | H34: KAIRO | I34: 1023 | J34: 1320 | K34: 1293 | L34: 834 | M34: =SUM(I34:L34) -> 4470 | N34: 993 | O34: 1239 | P34: 1236 | Q34: 735 | R34: =SUM(N34:Q34) -> 4203
A35: 23 | B35: =IF(C35="","",UPPER(TEXT(C35, "MMM"))) -> JUN | C35: 46179 | D35: =IFERROR(VLOOKUP(H35,KET!$B:$F,2,0),"") -> GRSM 4 | E35: =IFERROR(VLOOKUP(H35,KET!$B:$F,3,0),"") -> TASIK | F35: =IFERROR(VLOOKUP(H35,KET!$B:$F,4,0),"") -> FAHMI LUKMANUL HAKIM | G35: =IFERROR(VLOOKUP(H35,KET!$B:$F,5,0),"") -> GMM | H35: KAIRO | I35: 993 | J35: 1239 | K35: 1236 | L35: 735 | M35: =SUM(I35:L35) -> 4203 | N35: 954 | O35: 1179 | P35: 1164 | Q35: 654 | R35: =SUM(N35:Q35) -> 3951
A36: 23 | B36: =IF(C36="","",UPPER(TEXT(C36, "MMM"))) -> JUN | C36: 46179 | D36: =IFERROR(VLOOKUP(H36,KET!$B:$F,2,0),"") -> GRSM 4 | E36: =IFERROR(VLOOKUP(H36,KET!$B:$F,3,0),"") -> GARUT | F36: =IFERROR(VLOOKUP(H36,KET!$B:$F,4,0),"") -> FAHMI LUKMANUL HAKIM | G36: =IFERROR(VLOOKUP(H36,KET!$B:$F,5,0),"") -> GMM | H36: PRATAMA PUTRA BANYURESMI | I36: 225 | J36: 420 | K36: 445 | L36: 2180 | M36: =SUM(I36:L36) -> 3270 | N36: 185 | O36: 385 | P36: 405 | Q36: 2050 | R36: =SUM(N36:Q36) -> 3025
... A41: 23 | B41: =IF(C41="","",UPPER(TEXT(C41, "MMM"))) -> JUN | C41: 46179 | D41: =IFERROR(VLOOKUP(H41,KET!$B:$F,2,0),"") -> GRSM 3A | E41: =IFERROR(VLOOKUP(H41,KET!$B:$F,3,0),"") -> SUKABUMI | F41: =IFERROR(VLOOKUP(H41,KET!$B:$F,4,0),"") -> FAHMI LUKMANUL HAKIM | G41: =IFERROR(VLOOKUP(H41,KET!$B:$F,5,0),"") -> GMM | H41: MULTI GROSIR STASIUN | I41: 544 | J41: 1002 | K41: 655 | L41: 816 | M41: =SUM(I41:L41) -> 3017 | N41: 494 | O41: 954 | P41: 601 | Q41: 690 | R41: =SUM(N41:Q41) -> 2739
A42: 23 | B42: =IF(C42="","",UPPER(TEXT(C42, "MMM"))) -> JUN | C42: 46179 | D42: =IFERROR(VLOOKUP(H42,KET!$B:$F,2,0),"") -> GRSM 4 | E42: =IFERROR(VLOOKUP(H42,KET!$B:$F,3,0),"") -> TASIK | F42: =IFERROR(VLOOKUP(H42,KET!$B:$F,4,0),"") -> FAHMI LUKMANUL HAKIM | G42: =IFERROR(VLOOKUP(H42,KET!$B:$F,5,0),"") -> GMM | H42: YOGYA CIAMIS * | I42: 1216 | J42: 634 | K42: 665 | L42: - | M42: =SUM(I42:L42) -> 2515 | N42: 1182 | O42: 549 | P42: 616 | Q42: - | R42: =SUM(N42:Q42) -> 2347
A43: 23 | B43: =IF(C43="","",UPPER(TEXT(C43, "MMM"))) -> JUN | C43: 46180 | D43: =IFERROR(VLOOKUP(H43,KET!$B:$F,2,0),"") -> GRSM 4 | E43: =IFERROR(VLOOKUP(H43,KET!$B:$F,3,0),"") -> TASIK | F43: =IFERROR(VLOOKUP(H43,KET!$B:$F,4,0),"") -> FAHMI LUKMANUL HAKIM | G43: =IFERROR(VLOOKUP(H43,KET!$B:$F,5,0),"") -> GMM | H43: M ZAMZAM TK (M2) | I43: 860 | J43: 2000 | K43: 1102 | L43: 3500 | M43: =SUM(I43:L43) -> 7462 | N43: 788 | O43: 1910 | P43: 1012 | Q43: 3140 | R43: =SUM(N43:Q43) -> 6850
A44: 23 | B44: =IF(C44="","",UPPER(TEXT(C44, "MMM"))) -> JUN | C44: 46180 | D44: =IFERROR(VLOOKUP(H44,KET!$B:$F,2,0),"") -> GRSM 4 | E44: =IFERROR(VLOOKUP(H44,KET!$B:$F,3,0),"") -> TASIK | F44: =IFERROR(VLOOKUP(H44,KET!$B:$F,4,0),"") -> FAHMI LUKMANUL HAKIM | G44: =IFERROR(VLOOKUP(H44,KET!$B:$F,5,0),"") -> GMM | H44: KAIRO | I44: 927 | J44: 1125 | K44: 1104 | L44: 594 | M44: =SUM(I44:L44) -> 3750 | N44: 894 | O44: 1062 | P44: 1032 | Q44: 483 | R44: =SUM(N44:Q44) -> 3471
A45: 23 | B45: =IF(C45="","",UPPER(TEXT(C45, "MMM"))) -> JUN | C45: 46180 | D45: =IFERROR(VLOOKUP(H45,KET!$B:$F,2,0),"") -> GRSM 4 | E45: =IFERROR(VLOOKUP(H45,KET!$B:$F,3,0),"") -> TASIK | F45: =IFERROR(VLOOKUP(H45,KET!$B:$F,4,0),"") -> FAHMI LUKMANUL HAKIM | G45: =IFERROR(VLOOKUP(H45,KET!$B:$F,5,0),"") -> GMM | H45: KAIRO | I45: 954 | J45: 1179 | K45: 1164 | L45: 654 | M45: =SUM(I45:L45) -> 3951 | N45: 927 | O45: 1125 | P45: 1104 | Q45: 594 | R45: =SUM(N45:Q45) -> 3750
A46: 23 | B46: =IF(C46="","",UPPER(TEXT(C46, "MMM"))) -> JUN | C46: 46180 | D46: =IFERROR(VLOOKUP(H46,KET!$B:$F,2,0),"") -> GRSM 4 | E46: =IFERROR(VLOOKUP(H46,KET!$B:$F,3,0),"") -> KUNINGAN | F46: =IFERROR(VLOOKUP(H46,KET!$B:$F,4,0),"") -> FAHMI LUKMANUL HAKIM | G46: =IFERROR(VLOOKUP(H46,KET!$B:$F,5,0),"") -> GMM | H46: MITRA INDAH | I46: 212 | J46: 260 | K46: 616 | L46: 2019 | M46: =SUM(I46:L46) -> 3107 | N46: 145 | O46: 174 | P46: 516 | Q46: 1662 | R46: =SUM(N46:Q46) -> 2497
...
